<robot name="vs050">
	<gazebo>
		<plugin filename="libgazebo_ros_control.so" name="gazebo_ros_control">
			<robotNamespace>/vs050</robotNamespace>
		</plugin>
	</gazebo>
	<link name="world" />
	<joint name="joint_w" type="fixed">
		<parent link="world" />
		<child link="base_link" />
	</joint>
	<link name="base_link">
		<visual>
			<origin rpy="0 0 0" xyz="0 0 0" />
			<geometry>
				<mesh filename="package://denso_robot_descriptions/vs050_description/base_link.dae" scale="1 1 1" />
			</geometry>
		</visual>
		<collision>
			<origin rpy="0 0 0" xyz="0 0 0" />
			<geometry>
				<mesh filename="package://denso_robot_descriptions/vs050_description/base_link.dae" scale="1 1 1" />
			</geometry>
		</collision>
		<inertial>
			<mass value="1" />
			<origin rpy="0.000000 0.000000 0.000000" xyz="0.000000 0.000000 0.000000" />
			<inertia ixx="1" ixy="0" ixz="0" iyy="1" iyz="0" izz="1" />
		</inertial>
	</link>
	<link name="J1">
		<visual>
			<origin rpy="0 0 0" xyz="0 0 0" />
			<geometry>
				<mesh filename="package://denso_robot_descriptions/vs050_description/J1.dae" scale="1 1 1" />
			</geometry>
		</visual>
		<collision>
			<origin rpy="0 0 0" xyz="0 0 0" />
			<geometry>
				<mesh filename="package://denso_robot_descriptions/vs050_description/J1.dae" scale="1 1 1" />
			</geometry>
		</collision>
		<inertial>
			<mass value="1" />
			<origin rpy="0.000000 0.000000 0.000000" xyz="0.000000 0.000000 0.000000" />
			<inertia ixx="1" ixy="0" ixz="0" iyy="1" iyz="0" izz="1" />
		</inertial>
	</link>
	<joint name="joint_1" type="revolute">
		<parent link="base_link" />
		<child link="J1" />
		<origin rpy="0.000000 0.000000 0.000000" xyz="0.000000 0.000000 0.181500" />
		<axis xyz="-0.000000 -0.000000 1.000000" />
		<limit effort="1" lower="-2.96705972839036" upper="2.96705972839036" velocity="3.73064127613788" />
		<dynamics damping="0" friction="0" />
	</joint>
	<transmission name="trans_1">
		<type>transmission_interface/SimpleTransmission</type>
		<joint name="joint_1">
			<hardwareInterface>hardware_interface/PositionJointInterface</hardwareInterface>
		</joint>
		<actuator name="motor_1">
			<hardwareInterface>hardware_interface/PositionJointInterface</hardwareInterface>
			<mechanicalReduction>1</mechanicalReduction>
		</actuator>
	</transmission>
	<link name="J2">
		<visual>
			<origin rpy="0 0 0" xyz="0 0 0" />
			<geometry>
				<mesh filename="package://denso_robot_descriptions/vs050_description/J2.dae" scale="1 1 1" />
			</geometry>
		</visual>
		<collision>
			<origin rpy="0 0 0" xyz="0 0 0" />
			<geometry>
				<mesh filename="package://denso_robot_descriptions/vs050_description/J2.dae" scale="1 1 1" />
			</geometry>
		</collision>
		<inertial>
			<mass value="1" />
			<origin rpy="0.000000 0.000000 0.000000" xyz="0.000000 0.000000 0.000000" />
			<inertia ixx="1" ixy="0" ixz="0" iyy="1" iyz="0" izz="1" />
		</inertial>
	</link>
	<joint name="joint_2" type="revolute">
		<parent link="J1" />
		<child link="J2" />
		<origin rpy="0.000000 0.000000 0.000000" xyz="0.000000 0.000000 0.163500" />
		<axis xyz="-0.000000 1.000000 -0.000000" />
		<limit effort="1" lower="-2.0943951023932" upper="2.0943951023932" velocity="2.9845130209103" />
		<dynamics damping="0" friction="0" />
	</joint>
	<transmission name="trans_2">
		<type>transmission_interface/SimpleTransmission</type>
		<joint name="joint_2">
			<hardwareInterface>hardware_interface/PositionJointInterface</hardwareInterface>
		</joint>
		<actuator name="motor_2">
			<hardwareInterface>hardware_interface/PositionJointInterface</hardwareInterface>
			<mechanicalReduction>1</mechanicalReduction>
		</actuator>
	</transmission>
	<link name="J3">
		<visual>
			<origin rpy="0 0 0" xyz="0 0 0" />
			<geometry>
				<mesh filename="package://denso_robot_descriptions/vs050_description/J3.dae" scale="1 1 1" />
			</geometry>
		</visual>
		<collision>
			<origin rpy="0 0 0" xyz="0 0 0" />
			<geometry>
				<mesh filename="package://denso_robot_descriptions/vs050_description/J3.dae" scale="1 1 1" />
			</geometry>
		</collision>
		<inertial>
			<mass value="1" />
			<origin rpy="0.000000 0.000000 0.000000" xyz="0.000000 0.000000 0.000000" />
			<inertia ixx="1" ixy="0" ixz="0" iyy="1" iyz="0" izz="1" />
		</inertial>
	</link>
	<joint name="joint_3" type="revolute">
		<parent link="J2" />
		<child link="J3" />
		<origin rpy="0.000000 0.000000 0.000000" xyz="0.000000 0.000000 0.250000" />
		<axis xyz="-0.000000 1.000000 -0.000000" />
		<limit effort="1" lower="-2.0943951023932" upper="2.63544717051144" velocity="3.3857642159438" />
		<dynamics damping="0" friction="0" />
	</joint>
	<transmission name="trans_3">
		<type>transmission_interface/SimpleTransmission</type>
		<joint name="joint_3">
			<hardwareInterface>hardware_interface/PositionJointInterface</hardwareInterface>
		</joint>
		<actuator name="motor_3">
			<hardwareInterface>hardware_interface/PositionJointInterface</hardwareInterface>
			<mechanicalReduction>1</mechanicalReduction>
		</actuator>
	</transmission>
	<link name="J4">
		<visual>
			<origin rpy="0 0 0" xyz="0 0 0" />
			<geometry>
				<mesh filename="package://denso_robot_descriptions/vs050_description/J4.dae" scale="1 1 1" />
			</geometry>
		</visual>
		<collision>
			<origin rpy="0 0 0" xyz="0 0 0" />
			<geometry>
				<mesh filename="package://denso_robot_descriptions/vs050_description/J4.dae" scale="1 1 1" />
			</geometry>
		</collision>
		<inertial>
			<mass value="1" />
			<origin rpy="0.000000 0.000000 0.000000" xyz="0.000000 0.000000 0.000000" />
			<inertia ixx="1" ixy="0" ixz="0" iyy="1" iyz="0" izz="1" />
		</inertial>
	</link>
	<joint name="joint_4" type="revolute">
		<parent link="J3" />
		<child link="J4" />
		<origin rpy="0.000000 0.000000 0.000000" xyz="-0.010000 0.000000 0.119500" />
		<axis xyz="-0.000000 -0.000000 1.000000" />
		<limit effort="1" lower="-4.71238898038469" upper="4.71238898038469" velocity="3.73064127613788" />
		<dynamics damping="0" friction="0" />
	</joint>
	<transmission name="trans_4">
		<type>transmission_interface/SimpleTransmission</type>
		<joint name="joint_4">
			<hardwareInterface>hardware_interface/PositionJointInterface</hardwareInterface>
		</joint>
		<actuator name="motor_4">
			<hardwareInterface>hardware_interface/PositionJointInterface</hardwareInterface>
			<mechanicalReduction>1</mechanicalReduction>
		</actuator>
	</transmission>
	<link name="J5">
		<visual>
			<origin rpy="0 0 0" xyz="0 0 0" />
			<geometry>
				<mesh filename="package://denso_robot_descriptions/vs050_description/J5.dae" scale="1 1 1" />
			</geometry>
		</visual>
		<collision>
			<origin rpy="0 0 0" xyz="0 0 0" />
			<geometry>
				<mesh filename="package://denso_robot_descriptions/vs050_description/J5.dae" scale="1 1 1" />
			</geometry>
		</collision>
		<inertial>
			<mass value="1" />
			<origin rpy="0.000000 0.000000 0.000000" xyz="0.000000 0.000000 0.000000" />
			<inertia ixx="1" ixy="0" ixz="0" iyy="1" iyz="0" izz="1" />
		</inertial>
	</link>
	<joint name="joint_5" type="revolute">
		<parent link="J4" />
		<child link="J5" />
		<origin rpy="0.000000 0.000000 0.000000" xyz="0.000000 0.000000 0.135500" />
		<axis xyz="-0.000000 1.000000 -0.000000" />
		<limit effort="1" lower="-2.0943951023932" upper="2.0943951023932" velocity="2.87060410727889" />
		<dynamics damping="0" friction="0" />
	</joint>
	<transmission name="trans_5">
		<type>transmission_interface/SimpleTransmission</type>
		<joint name="joint_5">
			<hardwareInterface>hardware_interface/PositionJointInterface</hardwareInterface>
		</joint>
		<actuator name="motor_5">
			<hardwareInterface>hardware_interface/PositionJointInterface</hardwareInterface>
			<mechanicalReduction>1</mechanicalReduction>
		</actuator>
	</transmission>
	<link name="J6">
		<visual>
			<origin rpy="0 0 0" xyz="0 0 0" />
			<geometry>
				<mesh filename="package://denso_robot_descriptions/vs050_description/J6.dae" scale="1 1 1" />
			</geometry>
		</visual>
		<collision>
			<origin rpy="0 0 0" xyz="0 0 0" />
			<geometry>
				<mesh filename="package://denso_robot_descriptions/vs050_description/J6.dae" scale="1 1 1" />
			</geometry>
		</collision>
		<inertial>
			<mass value="1" />
			<origin rpy="0.000000 0.000000 0.000000" xyz="0.000000 0.000000 0.000000" />
			<inertia ixx="1" ixy="0" ixz="0" iyy="1" iyz="0" izz="1" />
		</inertial>
	</link>
	<joint name="joint_6" type="revolute">
		<parent link="J5" />
		<child link="J6" />
		<origin rpy="0.000000 0.000000 0.000000" xyz="0.000000 0.000000 0.070000" />
		<axis xyz="-0.000000 -0.000000 1.000000" />
		<limit effort="1" lower="-6.28318530717959" upper="6.28318530717959" velocity="5.96902604182061" />
		<dynamics damping="0" friction="0" />
	</joint>
	<transmission name="trans_6">
		<type>transmission_interface/SimpleTransmission</type>
		<joint name="joint_6">
			<hardwareInterface>hardware_interface/PositionJointInterface</hardwareInterface>
		</joint>
		<actuator name="motor_6">
			<hardwareInterface>hardware_interface/PositionJointInterface</hardwareInterface>
			<mechanicalReduction>1</mechanicalReduction>
		</actuator>
	</transmission>
</robot>